<?xml version="1.0" ?>

<robot name="mrm" xmlns:xacro="http://www.ros.org/wiki/xacro">

  <material name="blue">
    <color rgba="0 0 0.8 1"/>
  </material>

  <material name="white">
    <color rgba="1 1 1 1"/>
  </material>

  <link name="base_link">
      <visual>
          <origin rpy="1.575 0 0" xyz="0 0 0.0"/>
          <geometry>
              <cylinder radius="0.35" length="0.0"/>
          </geometry>
          <material name="black"/>
      </visual>
  </link>
  <joint name="base_link__link2" type="revolute">
      <axis xyz="0 0 1" />
      <limit effort="1000.0" lower="-3.14" upper="3.14" velocity="0.5" />
      <origin rpy="0 0 0" xyz="0 0 0"/>
      <parent link="base_link"/>
      <child link="link2"/>
  </joint>
  
  <link name="link2">
      <visual>
          <origin rpy="1.575 0 0" xyz="0 0.4 0"/>
          <geometry>
              <cylinder radius="0.15" length="0.8"/>
          </geometry>
          <material name="white"/>
      </visual>
      <collision>
        <geometry>
          <cylinder length="0.8" radius="0.15"/>
        </geometry>
      </collision>
      <inertial>
        <mass value="0.6"/>
        <inertia ixx="0.001" ixy="0.0" ixz="0.0" iyy="0.001" iyz="0.0" izz="0.001"/>
      </inertial>
  </link>

  <joint name="link2__link3" type="revolute">
      <axis xyz="0 0 1" />
      <limit effort="1000.0" lower="-3.14" upper="3.14" velocity="0.5" />
      <origin rpy="0 0 0" xyz="0 0.8 0"/>
      <parent link="link2"/>
      <child link="link3"/>
  </joint>
  
  <link name="link3">
      <visual>
          <origin rpy="1.575 0 0" xyz="0 0.4 0"/>
          <geometry>
              <cylinder radius="0.15" length="0.8"/>
          </geometry>
          <material name="blue"/>
      </visual>
      <collision>
        <geometry>
          <cylinder length="0.8" radius="0.15"/>
        </geometry>
      </collision>
      <inertial>
        <mass value="0.6"/>
        <inertia ixx="0.001" ixy="0.0" ixz="0.0" iyy="0.001" iyz="0.0" izz="0.001"/>
      </inertial>
  </link>
    <!-->
  <joint name="link3__link4" type="revolute">
      <axis xyz="0 1 0" />
      <limit effort="1000.0" lower="-3.14" upper="3.14" velocity="0.5" />
      <origin rpy="0 0 0" xyz="0 0 0.8"/>
      <parent link="link3"/>
      <child link="link4"/>
  </joint>


  <link name="link4">
      <visual>
          <origin rpy="0 0 0" xyz="0 0 0.4"/>
          <geometry>
              <cylinder radius="0.15" length="0.8"/>
          </geometry>
          <material name="blue"/>
      </visual>

  </link>
    <joint name="link4__link5" type="revolute">
      <axis xyz="0 1 0" />
      <limit effort="1000.0" lower="-3.14" upper="3.14" velocity="0.5" />
      <origin rpy="0 0 0" xyz="0 0 0.8"/>
      <parent link="link4"/>
      <child link="link5"/>
  </joint>

  <link name="link5">
      <visual>
          <origin rpy="0 0 0" xyz="0 0 0.4"/>
          <geometry>
              <cylinder radius="0.15" length="0.8"/>
          </geometry>
          <material name="blue"/>
      </visual>

  </link>
    <joint name="link5__link6" type="revolute">
      <axis xyz="0 1 0" />
      <limit effort="1000.0" lower="-3.14" upper="3.14" velocity="0.5" />
      <origin rpy="0 0 0" xyz="0 0 0.8"/>
      <parent link="link5"/>
      <child link="link6"/>
  </joint>
  
  <link name="link6">
      <visual>
          <origin rpy="0 0 0" xyz="0 0 0.4"/>
          <geometry>
              <cylinder radius="0.15" length="0.8"/>
          </geometry>
          <material name="blue"/>
      </visual>

  </link>
    <joint name="link6__link7" type="revolute">
      <axis xyz="0 1 0" />
      <limit effort="1000.0" lower="-3.14" upper="3.14" velocity="0.5" />
      <origin rpy="0 0 0" xyz="0 0 0.8"/>
      <parent link="link6"/>
      <child link="link7"/>
  </joint>


  <link name="link7">
      <visual>
          <origin rpy="0 0 0" xyz="0 0 0.125"/>
          <geometry>
              <cylinder radius="0.15" length="0.25"/>
          </geometry>
          <material name="blue"/>
      </visual>
  </link>
  -->
</robot>